Workbook
Name Dimensiones: [1]Listas!$A$2:$A$12
Name subsector: [1]Listas!$M$2:$M$5

Sheet Variable_indicador
A1: Descripción del indicador | H1: Metadato indicador | O1: Metadato variable indicador | U1: Variable indicador
A2: Dimensión | B2: Nombre del indicador | C2: subsector | D2: Unidad de medida | E2: Periodicidad | F2: Cobertura geográfica | G2: Cobertura temporal | H2: Titulo | I2: Nombre de la Organización | J2: Nombre del cargo | K2: Correo Electrónico | L2: Enlace | M2: Fecha | N2: Tipo de Fecha | O2: Nombre de la Organización2 | P2: Fecha 3 | Q2: Tipo de Fecha 4 | R2: Titulo5 | S2: Fuente | T2: Anexo | U2: Naturaleza del dato | V2: Tipo de dato variable | W2: Nombre de la variable | X2: Valor Variable
A3: Indique a que dimensión pertenece | B3: Indique el indicador que pertenece a la dimension | C3: Indique si es ( Energia, mineria, hidrocarburos o multisubsectorial) | E3: el indicador se mide por cual periodicidad | F3: alcance escala geografica | G3: año | H3: Nombre de la descripcion del indicador | I3: quien lo realizo | J3: escriba el nombre del profesional que esta a cargo de la metodologia del indicador | K3: correo del profesional esta a cargo de la metodologia del indicador | L3: link del documento que respalde la descripcion metodologica del indicador | M3: fecha que descripcion metodologica del indicador | O3: entidad encargada de la variable del indicador | P3: fecha de publicacion de la variable | R3: descripcion fuente de la información | T3: Anexar el documento si es necesario el derecho de petición | W3: Escriba el nombre de la variable del indicador | X3: Escriba el valor de la variable
A4: Normativa | B4: 1.Reconocimiento y protección de los derechos ambientales en la política sectorial de derechos humanos | C4: Multisubsectorial | D4: Porcentaje (%) | E4: Anual | F4: Nacional | G4: 2023 | H4: Evalúa los siguientes tres elementos: 1) la incorporación formal de los siguientes derechos: i) acceso a la información, ii) participación en materia ambiental, iii) acceso a justicia, iv) consulta previa y v) derecho a un ambiente sano (este listado puede aumentar en la medida que se reconozcan nuevos derechos ambientales en el ámbito internacional) en la política en derechos humanos del sector Minero Energético; 2) el porcentaje de ejecución de la política de derechos humanos y 3) la existencia de un presupuesto preciso para la ejecución de la política de derechos humanos | I4: Instituto de Estudios Ambientales -IDEA- | J4: Luis Fernando Sánchez Supelano | L4: 01. Reconocimiento y protección de los derechos ambientales.docx | M4: 28 de marzo de 2025 | N4: Creacion | O4: Ministerio de minas y energia | P4: 2023 | Q4: Publicacion | R4: Número de derechos para el cual existe una mención expresa en la Política de Derechos Humanos del Sector Minero-Energético , estrategia de transversalización del enfoque de DDHH, compromiso Político del Ministerio de Minas y Energía con la protección, respeto y promoción de los derechos en el marco de las operaciones del sector minero-energético,guía Introductoria en Empresas y Derechos Humanos y guía para la integración del enfoque de Derechos Humanos en el Desarrollo de las Políticas Públicas del Ministerio de Minas y Energía | S4: https://www.minenergia.gov.co/es/misional/gestión-social-y-ambiental/derechos-humanos/ | U4: Cuantitativo | V4: Entero (Integer int) | W4: 1.1.1. Número de derechos ambientales reconocidos en la política de derechos humanos del sector Minero Energético. | X4: 3
A5: Normativa | B5: 1.Reconocimiento y protección de los derechos ambientales en la política sectorial de derechos humanos | C5: Multisubsectorial | D5: Porcentaje (%) | E5: Anual | F5: Nacional | G5: 2023 | H5: Evalúa los siguientes tres elementos: 1) la incorporación formal de los siguientes derechos: i) acceso a la información, ii) participación en materia ambiental, iii) acceso a justicia, iv) consulta previa y v) derecho a un ambiente sano (este listado puede aumentar en la medida que se reconozcan nuevos derechos ambientales en el ámbito internacional) en la política en derechos humanos del sector Minero Energético; 2) el porcentaje de ejecución de la política de derechos humanos y 3) la existencia de un presupuesto preciso para la ejecución de la política de derechos humanos | I5: Instituto de Estudios Ambientales -IDEA- | J5: Luis Fernando Sánchez Supelano | L5: 01. Reconocimiento y protección de los derechos ambientales.docx | M5: 28 de marzo de 2025 | N5: Creacion | O5: Instituto de Estudios Ambientales -IDEA- | P5: marzo 31 de 2025 | Q5: Publicacion | R5: Numero de derechos humanos ambientales reconocidos internacionalmente : acceso a la información, derecho a la participación, consulta previa, ambiente sano y acceso a justicia. | S5: Fuente:Tabla 9. Revisión documentos derechos humanos, Producto E: Documento técnico que contenga la metodología ajustada y validada para la definición y estimación de los indicadores de gobernanza ambiental del sector minero energético y el desarrollo metodológico para el cálculo de los indicadores de gobernanza para el año 2023. | U5: Cuantitativo | V5: Entero (Integer int) | W5: 1.1.2. Número total de derechos ambientales reconocidos en derechos internacionales | X5: 5
A6: Normativa | B6: 1.Reconocimiento y protección de los derechos ambientales en la política sectorial de derechos humanos | C6: Multisubsectorial | D6: Porcentaje (%) | E6: Anual | F6: Nacional | G6: 2023 | H6: Evalúa los siguientes tres elementos: 1) la incorporación formal de los siguientes derechos: i) acceso a la información, ii) participación en materia ambiental, iii) acceso a justicia, iv) consulta previa y v) derecho a un ambiente sano (este listado puede aumentar en la medida que se reconozcan nuevos derechos ambientales en el ámbito internacional) en la política en derechos humanos del sector Minero Energético; 2) el porcentaje de ejecución de la política de derechos humanos y 3) la existencia de un presupuesto preciso para la ejecución de la política de derechos humanos | I6: Instituto de Estudios Ambientales -IDEA- | J6: Luis Fernando Sánchez Supelano | L6: 01. Reconocimiento y protección de los derechos ambientales.docx | M6: 28 de marzo de 2025 | N6: Creacion | O6: Instituto de Estudios Ambientales -IDEA- | P6: marzo 31 de 2025 | Q6: Publicacion | R6: Calculo del grado de incorporación formal de los derechos ambientales en la política sectorial de acuerdo a la siguiente formula | S6: Producto E: Documento técnico que contenga la metodología ajustada y validada para la definición y estimación de los indicadores de gobernanza ambiental del sector minero energético y el desarrollo metodológico para el cálculo de los indicadores de gobernanza para el año 2023. | U6: Cuantitativo | V6: Flotante (Float Double) | W6: 1.1.3.Puntuación reconocimiento formal derechos ambientales | X6: =X4/X5*100 -> 60
A7: Normativa | B7: 1.Reconocimiento y protección de los derechos ambientales en la política sectorial de derechos humanos | C7: Multisubsectorial | D7: Porcentaje (%) | E7: Anual | F7: Nacional | G7: 2023 | H7: Evalúa los siguientes tres elementos: 1) la incorporación formal de los siguientes derechos: i) acceso a la información, ii) participación en materia ambiental, iii) acceso a justicia, iv) consulta previa y v) derecho a un ambiente sano (este listado puede aumentar en la medida que se reconozcan nuevos derechos ambientales en el ámbito internacional) en la política en derechos humanos del sector Minero Energético; 2) el porcentaje de ejecución de la política de derechos humanos y 3) la existencia de un presupuesto preciso para la ejecución de la política de derechos humanos | I7: Instituto de Estudios Ambientales -IDEA- | J7: Luis Fernando Sánchez Supelano | L7: 01. Reconocimiento y protección de los derechos ambientales.docx | M7: 28 de marzo de 2025 | N7: Creacion | O7: Ministerio de minas y energia | R7: Número de acciones para implementar la Política Sectoria pública de Derechos Humanos | S7: Crear tabla para proximos años Producto E: Documento técnico que contenga la metodología ajustada y validada para la definición y estimación de los indicadores de gobernanza ambiental del sector minero energético y el desarrollo metodológico para el cálculo de los indicadores de gobernanza para el año 2023. | U7: Cuantitativo | V7: Entero (Integer int) | W7: 1.2.1. Número de acciones para implementar la Política Sectoria pública de Derechos Humanos | X7: 0
A8: Normativa | B8: 1.Reconocimiento y protección de los derechos ambientales en la política sectorial de derechos humanos | C8: Multisubsectorial | D8: Porcentaje (%) | E8: Anual | F8: Nacional | G8: 2023 | H8: Evalúa los siguientes tres elementos: 1) la incorporación formal de los siguientes derechos: i) acceso a la información, ii) participación en materia ambiental, iii) acceso a justicia, iv) consulta previa y v) derecho a un ambiente sano (este listado puede aumentar en la medida que se reconozcan nuevos derechos ambientales en el ámbito internacional) en la política en derechos humanos del sector Minero Energético; 2) el porcentaje de ejecución de la política de derechos humanos y 3) la existencia de un presupuesto preciso para la ejecución de la política de derechos humanos | I8: Instituto de Estudios Ambientales -IDEA- | J8: Luis Fernando Sánchez Supelano | L8: 01. Reconocimiento y protección de los derechos ambientales.docx | N8: Creacion | O8: Ministerio de minas y energia | R8: Acciones en específico para implementar la Política Sectoria pública de Derechos Humanos que cuente con los siguientes elementos i) cronograma; ii) indicadores, iii) esquema de seguimiento. | S8: https://www.minenergia.gov.co/es/misional/gestión-social-y-ambiental/derechos-humanos/ | U8: Cuantitativo | V8: Entero (Integer int) | W8: 1.2.2.Acciones en específico para implementar la Política Sectoria pública de Derechos Humanos | X8: 0
A9: Normativa | B9: 1.Reconocimiento y protección de los derechos ambientales en la política sectorial de derechos humanos | C9: Multisubsectorial | D9: Porcentaje (%) | E9: Anual | F9: Nacional | G9: 2023 | H9: Evalúa los siguientes tres elementos: 1) la incorporación formal de los siguientes derechos: i) acceso a la información, ii) participación en materia ambiental, iii) acceso a justicia, iv) consulta previa y v) derecho a un ambiente sano (este listado puede aumentar en la medida que se reconozcan nuevos derechos ambientales en el ámbito internacional) en la política en derechos humanos del sector Minero Energético; 2) el porcentaje de ejecución de la política de derechos humanos y 3) la existencia de un presupuesto preciso para la ejecución de la política de derechos humanos | I9: Instituto de Estudios Ambientales -IDEA- | J9: Luis Fernando Sánchez Supelano | L9: 01. Reconocimiento y protección de los derechos ambientales.docx | N9: Creacion | O9: Instituto de Estudios Ambientales -IDEA- | R9: Calculo del grado de incorporación al plan de acción e implementación Política de derechos humanos | S9: Producto E: Documento técnico que contenga la metodología ajustada y validada para la definición y estimación de los indicadores de gobernanza ambiental del sector minero energético y el desarrollo metodológico para el cálculo de los indicadores de gobernanza para el año 2023. | U9: Cuantitativo | V9: Entero (Integer int) | W9: 1.2.3. Puntuación plan de acción e implementación Política de derechos humanos | X9: 0
A10: Normativa | B10: 1.Reconocimiento y protección de los derechos ambientales en la política sectorial de derechos humanos | C10: Multisubsectorial | D10: Porcentaje (%) | E10: Anual | F10: Nacional | G10: 2023 | H10: Evalúa los siguientes tres elementos: 1) la incorporación formal de los siguientes derechos: i) acceso a la información, ii) participación en materia ambiental, iii) acceso a justicia, iv) consulta previa y v) derecho a un ambiente sano (este listado puede aumentar en la medida que se reconozcan nuevos derechos ambientales en el ámbito internacional) en la política en derechos humanos del sector Minero Energético; 2) el porcentaje de ejecución de la política de derechos humanos y 3) la existencia de un presupuesto preciso para la ejecución de la política de derechos humanos | I10: Instituto de Estudios Ambientales -IDEA- | J10: Luis Fernando Sánchez Supelano | L10: 01. Reconocimiento y protección de los derechos ambientales.docx | M10: 28 de marzo de 2025 | N10: Creacion | R10: Asignación presupuestal específica para la implementación de la Ppolítica Sectorial pública de derechos humanos s del sector (tomando como referencia los nombres de los proyectos de inversión que se encuentran en el presupuesto) | S10: https://www.minenergia.gov.co/es/ministerio/gestión/presupuesto/presupuesto-general-asignado/ Tabla 12. Revisión asignaciones presupuestales Producto E: Documento técnico que contenga la metodología ajustada y validada para la definición y estimación de los indicadores de gobernanza ambiental del sector minero energético y el desarrollo metodológico para el cálculo de los indicadores de gobernanza para el año 2023. | U10: Cualitativo | V10: Cadena de texto (String str). | W10: 1.3.1.Revisión asignaciones presupuestales | X10: Si
A11: Normativa | B11: 2.Contexto favorable para el ejercicio de los derechos ambientales | C11: Multisubsectorial | D11: Porcentaje (%) | R11: Con los datos tomados del sistema de alertas tempranas alertas que relacionan temas mineros (especialmente ligada a minería ilegal) 2023 | S11: https://alertastempranas.defensoria.gov.co/Alerta/Tablero | W11: 2.1.1.Número Total de alertas tempranas con seguimiento durante el año | X11: 8
A12: Normativa | B12: 2.Contexto favorable para el ejercicio de los derechos ambientales | R12: Con los datos tomados del sistema de alertas tempranas se revisa la información disponible en el sistema de alerta temprana de la defensoría del pueblo | W12: 2.1.2.Número Total de alertas tempranas durante el año | X12: 58
A13: Normativa | B13: 2.Contexto favorable para el ejercicio de los derechos ambientales | W13: 2.1.3.puntaje por Gestión frente alertas tempranas | X13: =X11/X12*100 -> 13.793103
A14: Normativa | B14: 2.Contexto favorable para el ejercicio de los derechos ambientales | W14: 2.2.1 número Total de alertas tempranas con cierre durante el año | X14: 3
A15: Normativa | B15: 2.Contexto favorable para el ejercicio de los derechos ambientales | W15: 2.2.2.Puntaje por resultados frente alertas tempranas | X15: =X14/X12*100 -> 5.1724138
A16: Normativa | B16: 3.Analisis de impacto regulatorio con dimension ambiental | W16: 3.1.1.Numero de documentos que contienen analisis de variables ambientales | X16: 3
A17: Normativa | B17: 3.Analisis de impacto regulatorio con dimension ambiental | W17: 3.1.2. Numero de estudios de impacto normativo realizados durante el año | X17: 4
A18: Normativa | B18: 3.Analisis de impacto regulatorio con dimension ambiental | W18: 3.1.3.AIN/Analisis de la variable ambiental | X18: =X16/X17*100 -> 75
A19: Normativa | B19: 4.Evaluación ex post de regulaciones | W19: 4.1.1.Consideración necesidad evaluación ex post | X19: Baja
A20: Normativa | B20: 4.Evaluación ex post de regulaciones | W20: 4.2.1.Numero de Documentos que contiene la variable ambiental evaluación expost | X20: 0
A21: Normativa | B21: 4.Evaluación ex post de regulaciones | W21: 4.2.1.Numero de Documentos de evaluación expost | X21: 2
A22: Normativa | B22: 4.Evaluación ex post de regulaciones | W22: 4.2.3.Cantidad de evaluaciones expost que incorporaron el análisis de la variable ambiental | X22: =X20/X21*100 -> 0
A23: Normativa | B23: 5. Procesos de consulta publica en la producción Normativa | W23: 5.1.1. Numero de decretos sometidos a consultas | X23: 4
A24: Normativa | B24: 5. Procesos de consulta publica en la producción Normativa | W24: 5.1.2 Numero de decretos | X24: 5
A25: Normativa | B25: 5. Procesos de consulta publica en la producción Normativa | W25: 5.1.3. Formula dcretos en consulta/N decretos | X25: =X23/X24*100 -> 80
A26: Analisis Institucional | B26: 6. Puntaje del sector de minas y energia en el indice de desempeño Institucional | W26: 6.1.1. promedio obtenido en el sector de minas y energia del resultado desempeño institucional | X26: 82.4 | Y26: 88.6
A27: Analisis Institucional | B27: 6. Puntaje del sector de minas y energia en el indice de desempeño Institucional | W27: 6.1.2.Puntaje correspondiente al índice de gobernanza | X27: 21
A28: Analisis Institucional | B28: 6. Puntaje del sector de minas y energia en el indice de desempeño Institucional | W28: 6.1.3.Puntaje obtenido en el Índice de desempeño instituciona | X28: 100
A29: Analisis Institucional | B29: 6. Puntaje del sector de minas y energia en el indice de desempeño Institucional | W29: 6.1.4.Puntaje obtenido en el año de referencia en el IDI (POIDI) | X29: =X26*X27/X28 -> 17.304
A30: Analisis Institucional | B30: 7. Coordinación interinstitucional | W30: 7.1.1.Puntuación existencia y funcionamiento mecanismos coordinación | X30: Alto
A31: Analisis Institucional | B31: 7. Coordinación interinstitucional | W31: 7.1.2.Nivel de cumplimiento de los instrumentos de coordinación interinstitucional a través de a) derecho de petición a la Oficina de Asuntos Ambientales y Sociales del Ministerio de Minas y Energía, b) revisiones informes de rendición de cuentas, c) informes de seguimiento a los planes formulados en el contexto de los mecanismos de coordinación interinstitucional | X31: 0
A32: Analisis Institucional | B32: 8. Acceso a la justicia | W32: 8.1.1. Numero de ordenes que no registran acciones pendientes de realizar y por tanto se entienden como cumplidas | X32: 4
A33: Analisis Institucional | B33: 8. Acceso a la justicia | W33: 8.1.2. Numero de procesos judiciales con órdenes directas para el Ministerio de Minas y Energía | X33: 27
A34: Analisis Institucional | B34: 8. Acceso a la justicia | W34: 8.1.3. Formula relacion que se entienden como cumplidas y numero de procesos directos del MME | X34: =X32/X33*100 -> 14.814815
A35: Sociales | B35: 9. Participación ciudadana | H35: 09. Hoja metodologica Participación ciudadana | U35: Cuantitativo | V35: Entero (Integer int) | W35: 9.1.1.sumatoria asistencia evento asistencia Informativo | X35: 17036
A36: Sociales | B36: 9. Participación ciudadana | H36: 09. Hoja metodologica Participación ciudadana | U36: Cuantitativo | V36: Entero (Integer int) | W36: 9.1.2. sumatoria asistencia evento Toma de Decisiones Participativas | X36: 7683
A37: Sociales | B37: 9. Participación ciudadana | H37: 09. Hoja metodologica Participación ciudadana | U37: Cuantitativo | V37: Entero (Integer int) | W37: 9.1.3.sumatoria asistencia evento Pedagógico | X37: 9657
A38: Sociales | B38: 9. Participación ciudadana | H38: 09. Hoja metodologica Participación ciudadana | U38: Cuantitativo | V38: Entero (Integer int) | W38: 9.1.4.sumatoria asistencia evento Planeación Participativa | X38: 12447
A39: Sociales | B39: 9. Participación ciudadana | H39: 09. Hoja metodologica Participación ciudadana | U39: Cuantitativo | V39: Entero (Integer int) | W39: 9.1.5.Resolución de Conflictos | X39: 579
A40: Sociales | B40: 9. Participación ciudadana | H40: 09. Hoja metodologica Participación ciudadana | U40: Cuantitativo | V40: Entero (Integer int) | W40: 91.6. Sumatorio asistentes | X40: =SUM(X35:X39) -> 47402
...

Sheet Puntaje asignado indicador
A2: N° | B2: Nombre de la valor indicador | C2: Nombre de la descripcion del indicador | D2: Valor del indicador | E2: Tipo de dato Indicador | F2: Nombre del valor puntaje asignado | G2: Puntaje asignado para el índice de gobernanza
A3: 1 | B3: Porcentaje de los derechos ambientales en la política sectorial de derechos humanos | C3: Se asigna puntaje definitivo para el indicador sumando los resultados obtenidos en el paso 4, 5 y 8 descrito en Producto E: Documento técnico que contenga la metodología ajustada y validada para la definición y estimación de los indicadores de gobernanza ambiental del sector minero energético y el desarrollo metodológico para el cálculo de los indicadores de gobernanza para el año 2023. | D3: =IF(Variable_indicador!X6>=80,5, IF(Variable_indicador!X6>=60,3.75, IF(Variable_indicador!X6>=40,2.5, IF(Variable_indicador!X6>=20,1.25, 0))))+IF(Variable_indicador!X9>80,12, IF(Variable_indicador!X9>60,9, IF(Variable_indicador!X9>40,6, IF(Variable_indicador!X9>20,3, 0))))+IF(Variable_indicador!X10="Si", 4, 0) -> 7.75 | E3: Flotante (Float Double) | F3: Puntaje indicador reconocimiento y protección derechos ambientales | G3: =D3 -> 7.75
A4: 2 | B4: Contexto favorable para el ejercicio de los derechos ambientales | D4: =IF(Variable_indicador!X13<=20,1.4,IF(Variable_indicador!X13<=40,2.8,IF(Variable_indicador!X13<=60,4.2,IF(Variable_indicador!X13<=80,5.6,7))))+IF(Variable_indicador!X15<=20,1.4,IF(Variable_indicador!X15<=40,2.8,IF(Variable_indicador!X15<=60,4.2,IF(Variable_indicador!X15<=80,5.6,7)))) -> 2.8 | F4: Puntuación contexto favorable ejercicio de los derechos ambientales | G4: =D4 -> 2.8
A5: 3 | B5: Analisis de impacto regulatorio con dimension ambiental | D5: =IF(Variable_indicador!X18<=20,0,IF(Variable_indicador!X18<=40,5.3,IF(Variable_indicador!X18<=60,10.5,IF(Variable_indicador!X18<=80,15.3,21)))) -> 15.3 | F5: Puntuación dimensión ambiental análisis de impacto normativo | G5: =D5 -> 15.3
A6: 4 | B6: Evaluación ex post de regulaciones | D6: =IF(Variable_indicador!X19="Alta", 5, IF(Variable_indicador!X19="Baja", 0, ""))+IF(Variable_indicador!X22<=20,1,IF(Variable_indicador!X22<=40,5.3,IF(Variable_indicador!X22<=60,7,IF(Variable_indicador!X22<=80,10.5,14)))) -> 1 | F6: Valoración puntaje evaluación ex post | G6: =D6 -> 1
A7: 5 | B7: Procesos de consulta publica en la producción Normativa | D7: =IF(Variable_indicador!X25<=20,1,IF(Variable_indicador!X25<=40,5.3,IF(Variable_indicador!X25<=60,10.5,IF(Variable_indicador!X23<=80,15.3,21)))) -> 15.3 | F7: Puntaje consulta pública normatividad | G7: =D7 -> 15.3
A8: 6 | B8: Puntaje del sector de minas y energia en el indice de desempeño Institucional | D8: =IF(Variable_indicador!X29<=20,4.2,IF(Variable_indicador!X29<=40,8.4,IF(Variable_indicador!X29<=60,12.6,IF(Variable_indicador!X29<=80,18.6,21)))) -> 4.2 | F8: Puntuación promedio desempeño institucional | G8: =D8 -> 4.2
A9: 7 | B9: Coordinación interinstitucional | D9: =IF(Variable_indicador!X30="Muy alto", 4, IF(Variable_indicador!X30="Alto", 3, IF(Variable_indicador!X30="Bajo", 2, IF(Variable_indicador!X30="Muy bajo", 1, ""))))+IF(Variable_indicador!X31<=20,1,IF(Variable_indicador!X31<=40,4,IF(Variable_indicador!X31<=60,7.5,IF(Variable_indicador!X31<=80,11,15)))) -> 4 | F9: Interpretación Puntaje total para el índice | G9: =D9 -> 4
A10: 8 | B10: Acceso a la justicia | D10: =IF(Variable_indicador!X31<=20,2,IF(Variable_indicador!X31<=40,4.25,IF(Variable_indicador!X31<=60,8.5,IF(Variable_indicador!X31<=80,12.3,19)))) -> 2 | F10: Puntuación cumplimiento órdenes judiciales | G10: =D10 -> 2
A11: 9 | B11: Participación ciudadana | D11: =((Variable_indicador!X35/Variable_indicador!$X$40)*Variable_indicador!X41)*100+((Variable_indicador!X36/Variable_indicador!$X$40)*Variable_indicador!X42)*100+((Variable_indicador!X37/Variable_indicador!$X$40)*Variable_indicador!X43)*100+((Variable_indicador!X38/Variable_indicador!$X$40)*Variable_indicador!X44)*100+((Variable_indicador!X39/Variable_indicador!$X$40)*Variable_indicador!X45)*100 -> 84.899371 | E11: Flotante (Float Double) | F11: Interpretación del indicador de Participación Ciudadana | G11: =IF(D11>=90,24, IF(D11>=75,19, IF(D11>=50,15, IF(D11>=30,8, 5)))) -> 19
A12: 10 | B12: Interacción de género y enfoque diferencial | D12: =(Variable_indicador!X72+Variable_indicador!X73+Variable_indicador!X74+Variable_indicador!X75+Variable_indicador!X76+Variable_indicador!X77)/6 -> 27.625029 | E12: Flotante (Float Double) | F12: Interpretación del indicador de interacción de género y enfoque diferencial | G12: =IF(D12>40,19, IF(D12>25,15, IF(D12>10,12, IF(AND(D12>=-10,D12<=10),10, IF(AND(D12>=-25,D12<-10),8,""))))) -> 15
A13: 11 | B13: Conflictividad socioambiental | D13: =((Variable_indicador!X78+Variable_indicador!X79+Variable_indicador!X80)/Variable_indicador!X82)*100 -> 35.251799 | E13: Flotante (Float Double) | F13: Interpretación del indicador de Conflictividad socioambiental | G13: =IF(D13<=9.99,24, IF(D13<=24.99,21, IF(D13<=49.99,18, IF(D13<=74.99,12, 6)))) -> 18
A14: 12 | B14: Cumplimiento a PQRSD | D14: =(Variable_indicador!X83+Variable_indicador!X84+Variable_indicador!X85+Variable_indicador!X86)/4 -> 94.3125 | E14: Flotante (Float Double) | F14: Interpretación del indicador de Cumplimiento a PQRSD | G14: =IF(D14>=95, 22, IF(D14>=90, 16, IF(D14>75, 10, IF(D14>=70, 5, "")))) -> 16
A15: 13 | B15: Variación de la demanda hídrica | D15: =Variable_indicador!X99+Variable_indicador!X100+Variable_indicador!X101 -> 1507.5 | E15: Flotante (Float Double) | F15: Interpretación de resultados para la variación de la demanda hídrica | G15: =IF(D15>0, 17, 8) -> 17
A16: 14 | B16: Variación de la huella hidrica azul | D16: =Variable_indicador!X108+Variable_indicador!X109+Variable_indicador!X110 -> 39.6 | G16: =IF(D16>0, 17, 8) -> 17
A17: 15 | B17: Variación del área compensada para el sector minero energético | D17: =SUM(Variable_indicador!X123:X131) -> 2975.8631 | F17: Criterios para calificar la variación del área compensada en el índice de gobernanza | G17: =IF(COUNTIF(Variable_indicador!X123:X131,">0")=9,19, IF(COUNTIF(Variable_indicador!X123:X131,">0")=6,14.25, IF(COUNTIF(Variable_indicador!X123:X131,"<0")=6,9.5, IF(COUNTIF(Variable_indicador!X123:X1855,"<0")=9,4.75) ) ) ) -> 9.5
A18: 16 | B18: Área de superposición de cada subsector minero energético con determinantes ambientales | D18: =(Variable_indicador!X175+Variable_indicador!X178+Variable_indicador!X179)/3 -> 43.950026 | F18: Interpretación de resultados para la superposición del sector minero energético con determinantes ambientales | G18: =_xlfn.IFS(D18>=76,4.75,D18>=51,9.5,D18>=26,14.25,D18>=0,19) -> 14.25
A19: 17 | B19: Área de superposición de cada subsector minero energetico con areas prioritarias de conservación | D19: =(Variable_indicador!X210+Variable_indicador!X213+Variable_indicador!X216)/3 -> 34.475552 | F19: Interpretación de resultados para la superposición del sector minero energéticos con áreas de distribución de especies importantes para la conservación | G19: =_xlfn.IFS(D19>=51,5,D19>=21,10,D19<20,19) -> 10
A20: 18 | B20: Variación de la generación de residuos peligrosos (RESPEL) por unidad producida | D20: =(Variable_indicador!X244+Variable_indicador!X245+Variable_indicador!X246)/3 -> 56.339555 | F20: Interpretación resultados indicador de variación de la generación de residuos peligrosos (Respel) por unidad producida | G20: =IF(Variable_indicador!X244<=-30,7,IF(AND(Variable_indicador!X244>-30,Variable_indicador!X244<0),4,IF(AND(Variable_indicador!X244>=0,Variable_indicador!X244<30),2,IF(Variable_indicador!X244>=30,1))))+IF(Variable_indicador!X245<=-30,7,IF(AND(Variable_indicador!X245>-30,Variable_indicador!X245<0),4,IF(AND(Variable_indicador!X245>=0,Variable_indicador!X245<30),2,IF(Variable_indicador!X245>=30,1))))+ IF(Variable_indicador!X246<=-30,7,IF(AND(Variable_indicador!X246>-30,Variable_indicador!X246<0),4,IF(AND(Variable_indicador!X246>=0,Variable_indicador!X246<30),2,IF(Variable_indicador!X246>=30,1)))) -> 4
A21: 19 | B21: Licenciamiento Ambiental | D21: =((Variable_indicador!X247+Variable_indicador!X249+Variable_indicador!X251)/(Variable_indicador!X248+Variable_indicador!X250+Variable_indicador!X252))*100 -> 64.285714 | E21: Flotante (Float Double) | F21: Interpretación resultados indicador licenciamiento ambiental | G21: =IF(D21>75,19,IF(D21>50,12,IF(D21>25,7,IF(D21>=0,3,"")))) -> 12
A22: 20 | B22: Procesos sancionatorios ambientales | D22: =((Variable_indicador!X253+Variable_indicador!X254+Variable_indicador!X255)/(Variable_indicador!X256+Variable_indicador!X257+Variable_indicador!X258))*100 -> 0 | F22: Interpretación resultados indicador procesos sancionatorios ambientales | G22: =IF(D22<=25,17,IF(D22<=50,13,IF(D22<=75,8,3))) -> 17
A23: 21 | B23: Variación de emisiones de gases de efecto invernadero (GEI) del sector | D23: =Variable_indicador!X421 -> -1.0436079 | F23: Interpretación del indicador de variación de emisiones de GEI | G23: =IF(D23>10,7,IF(D23>0,12,IF(D23>=-5,17,22))) -> 17
A24: 22 | B24: Tasa de variación del financiamiento climático | D24: =((Variable_indicador!X491-Variable_indicador!X490)/Variable_indicador!X491)*100 -> -96.1969 | F24: Interpretación del indicador de variación del financiamiento climático | G24: =IF(D24<0,6,IF(D24<=20%,11,IF(D24<=30%,16,21))) -> 6
A25: 23
A26: 24 | B26: Indice de derrames de hidrocarburos (IDH) | D26: =Variable_indicador!X543/Variable_indicador!X544 -> 2.7293082 | F26: Interpretación del indicador de accidentalidad sector hidrocarburos | G26: =IF(D26<=1,24,IF(D26<=2.5,18,IF(D26>4,6,12))) -> 12
A27: 25 | B27: Índice de gravedad de accidentes mineros (IGAM) | D27: =((Variable_indicador!X592+(3*Variable_indicador!X593))/Variable_indicador!X591) -> 4.1803279 | F27: Interpretación del indicador de accidentalidad minera | G27: =IF(D27<=1,24,IF(D27<=2.5,18,IF(D27>4,6,12))) -> 6
A28: 26 | B28: índice de severidad de accidentes eléctricos (ISAE) | D28: =((Variable_indicador!X602+(3*Variable_indicador!X603))/Variable_indicador!X604) -> 1.3301887 | F28: Interpretación de indicador de accidentalidad sector energético | G28: =IF(D28<=1,24,IF(D28<=2.5,18,IF(D28>4,6,12))) -> 18
A29: 27 | B29: Variación de la intensidad energética por subsector | D29: =((Variable_indicador!X637-Variable_indicador!X638)/Variable_indicador!X637) -> -0.0012113578 | F29: Interpretación del indicador de variación de la intensidad energética por subsector. | G29: =IF(D29>3.27,14,IF(D29>1.92,10,IF(D29>=0,6,2))) -> 2
A30: 28 | B30: Variación de la intensidad energética nacional | D30: =((Variable_indicador!X655-Variable_indicador!X656)/Variable_indicador!X655) -> 0.1570209 | F30: Interpretación del indicador de variación de la intensidad energética nacional | G30: =IF(D30>3.27,14,IF(D30>1.92,10,IF(D30>=0,6,2))) -> 6
A31: 29 | B31: Participación de las fncer en la matriz energética primaria | D31: =((Variable_indicador!X680-Variable_indicador!X679)/Variable_indicador!X680)*100 -> 9.262535 | F31: Interpretación del indicador de participación de las FNCER en matriz primaria | G31: =IF(D31>15.47,17,IF(D31>0,10,5)) -> 10
A32: 30 | B32: Participación de las FNCER en la matriz energética eléctrica. | D32: =((Variable_indicador!X691/Variable_indicador!X692)-(Variable_indicador!X685/Variable_indicador!X686))/(Variable_indicador!X691/Variable_indicador!X692)*100 -> 36.4448 | E32: Flotante (Float Double) | G32: =IF(D32>=50,17,IF(D32>=35,11,IF(D32>=15,6,1))) -> 11
A33: 31 | B33: Producción de minerales estratégicos y críticos para la TEJ. | D33: =Variable_indicador!X694-Variable_indicador!X693 -> 7302438.8 | F33: Interpretación del indicador de producción de minerales estratégicos y críticos para la TEJ. | G33: =IF(D33>=8000000,17,IF(D33>4000000,10, 0)) -> 10
A34: 32 | B34: Pobreza multidimensional en municipios productores de minerales estratégicos | D34: =((Variable_indicador!X700-Variable_indicador!X699)/Variable_indicador!X700)*100 -> 8.3333333 | F34: Interpretación del indicador de pobreza multidimensional en municipios productores de minerales estratégicos para la TEJ | G34: =IF(D34>20,17,IF(D34>=1,13,IF(D34=0,9,IF(D34>=-20,5,1)))) -> 13
A35: 33 | B35: Recaudo efectivo de regalías | D35: =(Variable_indicador!X701/Variable_indicador!X702)*100 -> 117.03663 | F35: Interpretación del indicador de recaudo efectivo de regalías | G35: =IF(D35>100,21,8) -> 21
A36: 34 | B36: Regalías destinadas al sector ambiente y desarrollo sostenible | D36: =(Variable_indicador!X703/Variable_indicador!X704)*100 -> 98.519794 | F36: Interpretación del indicador de regalías destinadas al sector ambiente y de desarrollo sostenible | G36: =IF(D36>=96,19,IF(D36>=91,16,IF(D36>=86,10,5))) -> 19
A37: 35 | B37: Variación de proyectos del SGR dirigidos al sector ambiente y desarrollo sostenible | D37: =((Variable_indicador!X705-Variable_indicador!X706)/Variable_indicador!X706)*100 -> 186.09272 | F37: Interpretación del indicador de variación de proyectos del SGR dirigidos al sector ambiente y desarrollo sostenible | G37: =IF(D37>150,14,IF(D37>=100,12,IF(D37>=70,7,5))) -> 14
A38: 36 | B38: Participación del sector minero energético en el PIB nacional | D38: =(Variable_indicador!X707/Variable_indicador!X708)*100 -> 6.2583221 | F38: Interpretación del indicador de participación del sector minero energético en el PIB nacional | G38: =IF(D38<=8.33,17,IF(D38<=13.81,12,IF(D38<=19.29,8,4))) -> 17
A39: 37 | B39: Participación del sector minero energético en las exportaciones del país | D39: =((Variable_indicador!X709/Variable_indicador!X710)*100) -> 52.52135 | F39: Interpretación del indicador de participación del sector minero energético en las exportaciones del país | G39: =IF(D39<=25,11,IF(D39<=44,7,IF(D39<=63,3.5,1))) -> 3.5
A40: 38 | B40: Pobreza multidimensional en municipios productores de hidrocarburos. | D40: =((Variable_indicador!X716-Variable_indicador!X713)/Variable_indicador!X716)*100 -> 6.3941406 | F40: Interpretación del Indicador de Diferencia Relativa Promedio IPM | G40: =IF(D40>20,14,IF(D40>=11,12,IF(D40>=1,10,IF(D40=0,8,IF(D40>=-10,6,IF(D40>=-20,4,2)))))) -> 10
A41: 39 | B41: Índice de cobertura y equidad territorial en municipios productores | D41: =((Variable_indicador!X717/Variable_indicador!X719)*(Variable_indicador!X718/Variable_indicador!X720))*100 -> 2.8199654 | F41: Interpretación del resultado del indicador de cobertura y equidad territorial en municipios productores | G41: =IF(D41>=15,24,IF(D41>=10,18,IF(D41>=5,12,6))) -> 6
...

Sheet Ponderado indicador
A1: N° | B1: Dimensión | C1: Objetivos | D1: Atributo | E1: Índice / Indicador | F1: Ficha Metodologica | G1: Criterio 1 ¿El indicador tiene un relación directa y significativa con la definición de gobernanza? Si/No | H1: Criterio 2 ¿El indicador puede ser mejorado a través de la gestión del Ministerio de Minas y Energía? Si/No | I1: Criterio 3 ¿El indicador tiene relación con el cumplimiento normativo del sector minero o ambiental ? Si/No | J1: Criterio 4¿La información requerida para la medición del indicador es generada por el Ministerio de Minas y Energía y/o sus entidades adscritas o vinculadas? Si/NO | K1: Criterio 5 ¿El indicador tiene una frecuencia de medición igual o inferior a un año? Si/No | L1: Criterio 6¿A partir de los resultados del indicador, el Ministerio de Minas y Energía puede emprender acciones que se concreten en la reglamentación del sector o en la definición de políticas, planes, programas o proyectos? Si/No | M1: Criterio 1 | N1: Criterio 2 | O1: Criterio 3 | P1: Criterio 4 | Q1: Criterio 5 | R1: Criterio 6 | S1: Criterio 7 Calificación promedio de la dimensión al que corresponde el indicador, en los talleres regionales | T1: Criterio 8 Calificación promedio del indicador en los talleres regionales | U1: Total | V1: Normalización | W1: Aproximación a la unidad
A2: 1 | B2: Análisis jurídico-normativo | C2: Robustez | D2: Legitimidad | E2: Reconocimiento y protección de los derechos ambientales en la política sectorial de derechos humanos | F2: 01. Reconocimiento y protección de los derechos ambientales.docx | G2: Si | H2: Si | I2: Si | J2: No | K2: Si | L2: Si | M2: =IF(G2="SI", 5, 1) -> 5 | N2: =IF(H2="SI", 5, 1) -> 5 | O2: =IF(I2="SI", 5, 1) -> 5 | P2: =IF(J2="SI", 5, 1) -> 1 | Q2: =IF(K2="SI", 5, 1) -> 5 | R2: =IF(L2="SI", 5, 1) -> 5 | S2: 4.3333333 | T2: 4.5142857 | U2: =SUM(M2:T2) -> 34.847619 | V2: =(Tabla1[[#This Row],[Total]]/$U$53)*1000 -> 21.467757 | W2: =ROUND(Tabla1[[#This Row],[Normalización]],0) -> 21
A3: 2 | B3: Análisis jurídico-normativo | C3: Robustez | D3: Legitimidad | E3: Contexto favorable para el ejercicio de los derechos ambientales | F3: 02. Contexto favorable para el ejercicio de los derechos ambientales.docx | G3: Si | H3: No | I3: No | J3: No | K3: Si | L3: No | M3: =IF(G3="SI", 5, 1) -> 5 | N3: =IF(H3="SI", 5, 1) -> 1 | O3: =IF(I3="SI", 5, 1) -> 1 | P3: =IF(J3="SI", 5, 1) -> 1 | Q3: =IF(K3="SI", 5, 1) -> 5 | R3: =IF(L3="SI", 5, 1) -> 1 | S3: 4.3333333 | T3: 4.3529412 | U3: =SUM(M3:T3) -> 22.686275 | V3: =(Tabla1[[#This Row],[Total]]/$U$53)*1000 -> 13.975802 | W3: =ROUND(Tabla1[[#This Row],[Normalización]],0) -> 14
A4: 3 | B4: Análisis jurídico-normativo | C4: Equidad | D4: Reconocimiento, Participación, Transparencia | E4: Análisis de impacto regulatorio con dimensión ambiental | F4: 03. Análisis de impacto regulatorio con dimensión ambiental.docx | G4: Si | H4: Si | I4: Si | J4: Si | K4: Si | L4: No | M4: =IF(G4="SI", 5, 1) -> 5 | N4: =IF(H4="SI", 5, 1) -> 5 | O4: =IF(I4="SI", 5, 1) -> 5 | P4: =IF(J4="SI", 5, 1) -> 5 | Q4: =IF(K4="SI", 5, 1) -> 5 | R4: =IF(L4="SI", 5, 1) -> 1 | S4: 4.3333333 | T4: 4.03125 | U4: =SUM(M4:T4) -> 34.364583 | V4: =(Tabla1[[#This Row],[Total]]/$U$53)*1000 -> 21.170185 | W4: =ROUND(Tabla1[[#This Row],[Normalización]],0) -> 21
A5: 4 | B5: Análisis jurídico-normativo | C5: Equidad | D5: Reconocimiento, Participación, Transparencia | E5: Evaluación ex post de regulaciones | F5: 04. Evaluación ex post de regulaciones.docx | G5: No | H5: Si | I5: Si | J5: Si | K5: Si | L5: No | M5: =IF(G5="SI", 5, 1) -> 1 | N5: =IF(H5="SI", 5, 1) -> 5 | O5: =IF(I5="SI", 5, 1) -> 5 | P5: =IF(J5="SI", 5, 1) -> 5 | Q5: =IF(K5="SI", 5, 1) -> 5 | R5: =IF(L5="SI", 5, 1) -> 1 | S5: 4.3333333 | T5: 4.1515152 | U5: =SUM(M5:T5) -> 30.484848 | V5: =(Tabla1[[#This Row],[Total]]/$U$53)*1000 -> 18.780087 | W5: =ROUND(Tabla1[[#This Row],[Normalización]],0) -> 19
A6: 5 | B6: Análisis jurídico-normativo | C6: Equidad | D6: Reconocimiento, Participación, Transparencia | E6: Procesos de consulta pública en la producción normativa | F6: 05. Procesos de consulta pública en la producción normativa.docx | G6: Si | H6: Si | I6: Si | J6: Si | K6: Si | L6: No | M6: =IF(G6="SI", 5, 1) -> 5 | N6: =IF(H6="SI", 5, 1) -> 5 | O6: =IF(I6="SI", 5, 1) -> 5 | P6: =IF(J6="SI", 5, 1) -> 5 | Q6: =IF(K6="SI", 5, 1) -> 5 | R6: =IF(L6="SI", 5, 1) -> 1 | S6: 4.3333333 | T6: 4.3636364 | U6: =SUM(M6:T6) -> 34.69697 | V6: =(Tabla1[[#This Row],[Total]]/$U$53)*1000 -> 21.37495 | W6: =ROUND(Tabla1[[#This Row],[Normalización]],0) -> 21
A7: 6 | B7: Análisis institucional | C7: Efectividad | D7: Coordinación, dirección, capacidad y eficiencia | E7: Puntaje del sector de minas y energía en el índice de Desempeño Institucional | F7: 06. Puntaje del SME en el Índice de Desempaño Institucional.docx | G7: Si | H7: Si | I7: Si | J7: No | K7: Si | L7: Si | M7: =IF(G7="SI", 5, 1) -> 5 | N7: =IF(H7="SI", 5, 1) -> 5 | O7: =IF(I7="SI", 5, 1) -> 5 | P7: =IF(J7="SI", 5, 1) -> 1 | Q7: =IF(K7="SI", 5, 1) -> 5 | R7: =IF(L7="SI", 5, 1) -> 5 | S7: 4.4333333 | T7: 4.2941176 | U7: =SUM(M7:T7) -> 34.727451 | V7: =(Tabla1[[#This Row],[Total]]/$U$53)*1000 -> 21.393728 | W7: =ROUND(Tabla1[[#This Row],[Normalización]],0) -> 21
A8: 7 | B8: Análisis institucional | C8: Efectividad | D8: Coordinación, dirección, capacidad y eficiencia | E8: Coordinación intersectorial | F8: 07. Coordinación interinstitucional.docx | G8: Si | H8: No | I8: Si | J8: No | K8: Si | L8: Si | M8: =IF(G8="SI", 5, 1) -> 5 | N8: =IF(H8="SI", 5, 1) -> 1 | O8: =IF(I8="SI", 5, 1) -> 5 | P8: =IF(J8="SI", 5, 1) -> 1 | Q8: =IF(K8="SI", 5, 1) -> 5 | R8: =IF(L8="SI", 5, 1) -> 5 | S8: 4.4333333 | T8: 4.4705882 | U8: =SUM(M8:T8) -> 30.903922 | V8: =(Tabla1[[#This Row],[Total]]/$U$53)*1000 -> 19.038256 | W8: =ROUND(Tabla1[[#This Row],[Normalización]],0) -> 19
A9: 8 | B9: Análisis institucional | C9: Equidad | D9: Reconocimiento y justicia | E9: Acceso a justicia | F9: 08. Acceso a justicia.docx | G9: Si | H9: No | I9: Si | J9: No | K9: Si | L9: Si | M9: =IF(G9="SI", 5, 1) -> 5 | N9: =IF(H9="SI", 5, 1) -> 1 | O9: =IF(I9="SI", 5, 1) -> 5 | P9: =IF(J9="SI", 5, 1) -> 1 | Q9: =IF(K9="SI", 5, 1) -> 5 | R9: =IF(L9="SI", 5, 1) -> 5 | S9: 4.4333333 | T9: 4.6285714 | U9: =SUM(M9:T9) -> 31.061905 | V9: =(Tabla1[[#This Row],[Total]]/$U$53)*1000 -> 19.135581 | W9: =ROUND(Tabla1[[#This Row],[Normalización]],0) -> 19
A10: 9 | B10: Social | C10: Equidad | D10: Participación | E10: Participación ciudadana | F10: 09. Participación Ciudadana.docx | G10: Si | H10: Si | I10: Si | J10: Si | K10: Si | L10: Si | M10: =IF(G10="SI", 5, 1) -> 5 | N10: =IF(H10="SI", 5, 1) -> 5 | O10: =IF(I10="SI", 5, 1) -> 5 | P10: =IF(J10="SI", 5, 1) -> 5 | Q10: =IF(K10="SI", 5, 1) -> 5 | R10: =IF(L10="SI", 5, 1) -> 5 | S10: 4.62 | T10: 4.68 | U10: =SUM(M10:T10) -> 39.3 | V10: =(Tabla1[[#This Row],[Total]]/$U$53)*1000 -> 24.210631 | W10: =ROUND(Tabla1[[#This Row],[Normalización]],0) -> 24
A11: 10 | B11: Social | C11: Equidad | D11: Reconocimiento | E11: Interacción de género y enfoque diferencial | F11: 10. Interacción de género y enfoque diferencial.docx | G11: Si | H11: Si | I11: No | J11: Si | K11: Si | L11: No | M11: =IF(G11="SI", 5, 1) -> 5 | N11: =IF(H11="SI", 5, 1) -> 5 | O11: =IF(I11="SI", 5, 1) -> 1 | P11: =IF(J11="SI", 5, 1) -> 5 | Q11: =IF(K11="SI", 5, 1) -> 5 | R11: =IF(L11="SI", 5, 1) -> 1 | S11: 4.62 | T11: 4.49 | U11: =SUM(M11:T11) -> 31.11 | V11: =(Tabla1[[#This Row],[Total]]/$U$53)*1000 -> 19.16521 | W11: =ROUND(Tabla1[[#This Row],[Normalización]],0) -> 19
A12: 11 | B12: Social | C12: Equidad | D12: Justicia | E12: Conflictividad socioambiental | F12: 11. Conflictividad Socioambiental.docx | G12: Si | H12: Si | I12: Si | J12: Si | K12: Si | L12: Si | M12: =IF(G12="SI", 5, 1) -> 5 | N12: =IF(H12="SI", 5, 1) -> 5 | O12: =IF(I12="SI", 5, 1) -> 5 | P12: =IF(J12="SI", 5, 1) -> 5 | Q12: =IF(K12="SI", 5, 1) -> 5 | R12: =IF(L12="SI", 5, 1) -> 5 | S12: 4.62 | T12: 4.69 | U12: =SUM(M12:T12) -> 39.31 | V12: =(Tabla1[[#This Row],[Total]]/$U$53)*1000 -> 24.216792 | W12: =ROUND(Tabla1[[#This Row],[Normalización]],0) -> 24
A13: 12 | B13: Social | C13: Equidad | D13: Transparencia | E13: Cumplimiento a PQRSD | F13: 12. Cumplimiento a PQRSD (peticiones, quejas, reclamos, sugerencias y denuncias).docx | G13: Si | H13: Si | I13: Si | J13: Si | K13: Si | L13: No | M13: =IF(G13="SI", 5, 1) -> 5 | N13: =IF(H13="SI", 5, 1) -> 5 | O13: =IF(I13="SI", 5, 1) -> 5 | P13: =IF(J13="SI", 5, 1) -> 5 | Q13: =IF(K13="SI", 5, 1) -> 5 | R13: =IF(L13="SI", 5, 1) -> 1 | S13: 4.62 | T13: 4.49 | U13: =SUM(M13:T13) -> 35.11 | V13: =(Tabla1[[#This Row],[Total]]/$U$53)*1000 -> 21.629396 | W13: =ROUND(Tabla1[[#This Row],[Normalización]],0) -> 22
... A32: 31 | B32: Transición energética justa | C32: Receptividad | D32: Flexibilidad y Adaptación | E32: Producción de minerales estratégicos y críticos para la TEJ. | F32: 31. Producción de Minerales Estratégicos y Críticos para la TEJ.docx | G32: Si | H32: No | I32: No | J32: Si | K32: Si | L32: No | M32: =IF(G32="SI", 5, 1) -> 5 | N32: =IF(H32="SI", 5, 1) -> 1 | O32: =IF(I32="SI", 5, 1) -> 1 | P32: =IF(J32="SI", 5, 1) -> 5 | Q32: =IF(K32="SI", 5, 1) -> 5 | R32: =IF(L32="SI", 5, 1) -> 1 | S32: 4.52 | T32: 4.28 | U32: =SUM(M32:T32) -> 26.8 | V32: =(Tabla1[[#This Row],[Total]]/$U$53)*1000 -> 16.510049 | W32: =ROUND(Tabla1[[#This Row],[Normalización]],0) -> 17
A33: 32 | B33: Transición energética justa | D33: Equidad | E33: Pobreza multidimensional en municipios productores de minerales estratégicos | F33: 32. Pobreza multidimensional en municipios productores de minerales estratégicos para la Transición Energética Justa..docx | G33: Si | H33: No | I33: No | J33: No | K33: Si | L33: Si | M33: =IF(G33="SI", 5, 1) -> 5 | N33: =IF(H33="SI", 5, 1) -> 1 | O33: =IF(I33="SI", 5, 1) -> 1 | P33: =IF(J33="SI", 5, 1) -> 1 | Q33: =IF(K33="SI", 5, 1) -> 5 | R33: =IF(L33="SI", 5, 1) -> 5 | S33: 4.52 | T33: 4.52 | U33: =SUM(M33:T33) -> 27.04 | V33: =(Tabla1[[#This Row],[Total]]/$U$53)*1000 -> 16.6579 | W33: =ROUND(Tabla1[[#This Row],[Normalización]],0) -> 17
A34: 33 | B34: Económica | C34: Efectividad | D34: Eficiencia | E34: Recaudo efectivo de regalías | F34: 33. Recaudo efectivo de Regalías.docx | G34: Si | H34: Si | I34: Si | J34: No | K34: Si | L34: Si | M34: =IF(G34="SI", 5, 1) -> 5 | N34: =IF(H34="SI", 5, 1) -> 5 | O34: =IF(I34="SI", 5, 1) -> 5 | P34: =IF(J34="SI", 5, 1) -> 1 | Q34: =IF(K34="SI", 5, 1) -> 5 | R34: =IF(L34="SI", 5, 1) -> 5 | S34: 4.22 | T34: 4.345 | U34: =SUM(M34:T34) -> 34.565 | V34: =(Tabla1[[#This Row],[Total]]/$U$53)*1000 -> 21.293651 | W34: =ROUND(Tabla1[[#This Row],[Normalización]],0) -> 21
A35: 34 | B35: Económica | C35: Efectividad | D35: Eficiencia | E35: Regalías destinadas al sector ambiente y desarrollo sostenible | F35: 34. Regalías destinadas al sector Ambiente y Desarrollo Sostenible.docx | G35: No | H35: Si | I35: Si | J35: No | K35: Si | L35: Si | M35: =IF(G35="SI", 5, 1) -> 1 | N35: =IF(H35="SI", 5, 1) -> 5 | O35: =IF(I35="SI", 5, 1) -> 5 | P35: =IF(J35="SI", 5, 1) -> 1 | Q35: =IF(K35="SI", 5, 1) -> 5 | R35: =IF(L35="SI", 5, 1) -> 5 | S35: 4.22 | T35: 4.655 | U35: =SUM(M35:T35) -> 30.875 | V35: =(Tabla1[[#This Row],[Total]]/$U$53)*1000 -> 19.020439 | W35: =ROUND(Tabla1[[#This Row],[Normalización]],0) -> 19
A36: 35 | B36: Económica | C36: Efectividad | D36: Eficiencia | E36: Variación de proyectos del SGR dirigidos al sector ambiente y desarrollo sostenible | F36: 35. Variación del número de proyectos del SGR dirigidos al sector Ambiente y Desarrollo Sostenible.docx | G36: No | H36: No | I36: No | J36: No | K36: Si | L36: Si | M36: =IF(G36="SI", 5, 1) -> 1 | N36: =IF(H36="SI", 5, 1) -> 1 | O36: =IF(I36="SI", 5, 1) -> 1 | P36: =IF(J36="SI", 5, 1) -> 1 | Q36: =IF(K36="SI", 5, 1) -> 5 | R36: =IF(L36="SI", 5, 1) -> 5 | S36: 4.22 | T36: 4.28 | U36: =SUM(M36:T36) -> 22.5 | V36: =(Tabla1[[#This Row],[Total]]/$U$53)*1000 -> 13.861048 | W36: =ROUND(Tabla1[[#This Row],[Normalización]],0) -> 14
A37: 36 | B37: Económica | C37: Efectividad | D37: Eficiencia | E37: Participación del sector minero energético en el PIB nacional | F37: 36. Participación del sector Minero Energético en el PIB nacional.docx | G37: Si | H37: No | I37: Si | J37: No | K37: Si | L37: No | M37: =IF(G37="SI", 5, 1) -> 5 | N37: =IF(H37="SI", 5, 1) -> 1 | O37: =IF(I37="SI", 5, 1) -> 5 | P37: =IF(J37="SI", 5, 1) -> 1 | Q37: =IF(K37="SI", 5, 1) -> 5 | R37: =IF(L37="SI", 5, 1) -> 1 | S37: 4.22 | T37: 4.69 | U37: =SUM(M37:T37) -> 26.91 | V37: =(Tabla1[[#This Row],[Total]]/$U$53)*1000 -> 16.577814 | W37: =ROUND(Tabla1[[#This Row],[Normalización]],0) -> 17
A38: 37 | B38: Económica | C38: Efectividad | D38: Eficiencia | E38: Participación del sector minero energético en las exportaciones del país | F38: 37. Participación del sector Minero Energético en las exportaciones del país.docx | G38: No | H38: No | I38: No | J38: No | K38: Si | L38: No | M38: =IF(G38="SI", 5, 1) -> 1 | N38: =IF(H38="SI", 5, 1) -> 1 | O38: =IF(I38="SI", 5, 1) -> 1 | P38: =IF(J38="SI", 5, 1) -> 1 | Q38: =IF(K38="SI", 5, 1) -> 5 | R38: =IF(L38="SI", 5, 1) -> 1 | S38: 4.22 | T38: 4.31 | U38: =SUM(M38:T38) -> 18.53 | V38: =(Tabla1[[#This Row],[Total]]/$U$53)*1000 -> 11.415343 | W38: =ROUND(Tabla1[[#This Row],[Normalización]],0) -> 11
A39: 38 | B39: Subsector de hidrocarburos | C39: Equidad | D39: Justicia | E39: Pobreza multidimensional en municipios productores de hidrocarburos. | F39: 38. Pobreza multidimensional en municipios productores de hidrocarburos..docx | G39: Si | H39: Si | I39: No | J39: No | K39: No | L39: No | M39: =IF(G39="SI", 5, 1) -> 5 | N39: =IF(H39="SI", 5, 1) -> 5 | O39: =IF(I39="SI", 5, 1) -> 1 | P39: =IF(J39="SI", 5, 1) -> 1 | Q39: =IF(K39="SI", 5, 1) -> 1 | R39: =IF(L39="SI", 5, 1) -> 1 | S39: 4.23 | T39: 4.61 | U39: =SUM(M39:T39) -> 22.84 | V39: =(Tabla1[[#This Row],[Total]]/$U$53)*1000 -> 14.070504 | W39: =ROUND(Tabla1[[#This Row],[Normalización]],0) -> 14
A40: 39 | B40: Subsector de hidrocarburos | C40: Equidad | D40: Justicia | E40: Índice de cobertura y equidad territorial en municipios productores | F40: 39. Cobertura y equidad territorial en municipios productores de hidrocarburos.docx | G40: Si | H40: Si | I40: Si | J40: Si | K40: Si | L40: Si | M40: =IF(G40="SI", 5, 1) -> 5 | N40: =IF(H40="SI", 5, 1) -> 5 | O40: =IF(I40="SI", 5, 1) -> 5 | P40: =IF(J40="SI", 5, 1) -> 5 | Q40: =IF(K40="SI", 5, 1) -> 5 | R40: =IF(L40="SI", 5, 1) -> 5 | S40: 4.23 | T40: 4.43 | U40: =SUM(M40:T40) -> 38.66 | V40: =(Tabla1[[#This Row],[Total]]/$U$53)*1000 -> 23.816362 | W40: =ROUND(Tabla1[[#This Row],[Normalización]],0) -> 24
A41: 40 | B41: Subsector de hidrocarburos | C41: Receptividad | D41: Anticipación | E41: Participación de los hidrocarburos en la matriz energética (IPHME) | F41: 40. Participación de los hidrocarburos en la matriz energética (IPHME).docx | G41: Si | H41: Si | I41: No | J41: Si | K41: Si | L41: Si | M41: =IF(G41="SI", 5, 1) -> 5 | N41: =IF(H41="SI", 5, 1) -> 5 | O41: =IF(I41="SI", 5, 1) -> 1 | P41: =IF(J41="SI", 5, 1) -> 5 | Q41: =IF(K41="SI", 5, 1) -> 5 | R41: =IF(L41="SI", 5, 1) -> 5 | S41: 4.23 | T41: 4.23 | U41: =SUM(M41:T41) -> 34.46 | V41: =(Tabla1[[#This Row],[Total]]/$U$53)*1000 -> 21.228966 | W41: =ROUND(Tabla1[[#This Row],[Normalización]],0) -> 21
A42: 41 | B42: Subsector de hidrocarburos | C42: Efectividad | D42: Información | E42: Variación del stock de hidrocarburos | F42: 41. Variación del stock de hidrocarburos.docx | G42: Si | H42: Si | I42: No | J42: Si | K42: Si | L42: Si | M42: =IF(G42="SI", 5, 1) -> 5 | N42: =IF(H42="SI", 5, 1) -> 5 | O42: =IF(I42="SI", 5, 1) -> 1 | P42: =IF(J42="SI", 5, 1) -> 5 | Q42: =IF(K42="SI", 5, 1) -> 5 | R42: =IF(L42="SI", 5, 1) -> 5 | S42: 4.23 | T42: 4.25 | U42: =SUM(M42:T42) -> 34.48 | V42: =(Tabla1[[#This Row],[Total]]/$U$53)*1000 -> 21.241287 | W42: =ROUND(Tabla1[[#This Row],[Normalización]],0) -> 21
A43: 42 | B43: Subsector de hidrocarburos | C43: Efectividad | D43: Información | E43: Disponibilidad de reservas de hidrocarburos (R/P) | F43: 42. Disponibilidad de reservas de hidrocarburos.docx | G43: Si | H43: Si | I43: No | J43: Si | K43: Si | L43: Si | M43: =IF(G43="SI", 5, 1) -> 5 | N43: =IF(H43="SI", 5, 1) -> 5 | O43: =IF(I43="SI", 5, 1) -> 1 | P43: =IF(J43="SI", 5, 1) -> 5 | Q43: =IF(K43="SI", 5, 1) -> 5 | R43: =IF(L43="SI", 5, 1) -> 5 | S43: 4.23 | T43: 4.32 | U43: =SUM(M43:T43) -> 34.55 | V43: =(Tabla1[[#This Row],[Total]]/$U$53)*1000 -> 21.28441 | W43: =ROUND(Tabla1[[#This Row],[Normalización]],0) -> 21
A44: 43 | B44: Subsector de hidrocarburos | C44: Efectividad | D44: Información | E44: Tasa de extracción de hidrocarburos (TEH) | F44: 43. Tasa de extracción de hidrocarburos (TEH).docx | G44: Si | H44: Si | I44: No | J44: Si | K44: Si | L44: Si | M44: =IF(G44="SI", 5, 1) -> 5 | N44: =IF(H44="SI", 5, 1) -> 5 | O44: =IF(I44="SI", 5, 1) -> 1 | P44: =IF(J44="SI", 5, 1) -> 5 | Q44: =IF(K44="SI", 5, 1) -> 5 | R44: =IF(L44="SI", 5, 1) -> 5 | S44: 4.23 | T44: 4.25 | U44: =SUM(M44:T44) -> 34.48 | V44: =(Tabla1[[#This Row],[Total]]/$U$53)*1000 -> 21.241287 | W44: =ROUND(Tabla1[[#This Row],[Normalización]],0) -> 21
A45: 44 | B45: Subsector de minería | C45: Robustez | D45: Legitimidad - Cumplimiento legal | E45: Superposición de títulos mineros activos con áreas ambientales excluibles, restrictivas e informativas para la minería | F45: 44. Superposición de títulos mineros activos con áreas ambientales excluibles....docx | G45: Si | H45: Si | I45: Si | J45: Si | K45: Si | L45: Si | M45: =IF(G45="SI", 5, 1) -> 5 | N45: =IF(H45="SI", 5, 1) -> 5 | O45: =IF(I45="SI", 5, 1) -> 5 | P45: =IF(J45="SI", 5, 1) -> 5 | Q45: =IF(K45="SI", 5, 1) -> 5 | R45: =IF(L45="SI", 5, 1) -> 5 | S45: 4.12 | T45: 4.34 | U45: =SUM(M45:T45) -> 38.46 | V45: =(Tabla1[[#This Row],[Total]]/$U$53)*1000 -> 23.693152 | W45: =ROUND(Tabla1[[#This Row],[Normalización]],0) -> 24
... A52: 51 | B52: Subsector de energía eléctrica | C52: Equidad | D52: Participación – Acceso a la Información | E52: Porcentaje de Informes de Sostenibilidad anuales publicados por empresas generadoras del país. | F52: 51. Porcentaje de Informes de Sostenibilidad anuales publicados por empresas generadoras del país..docx | G52: Si | H52: Si | I52: Si | J52: No | K52: Si | L52: Si | M52: =IF(G52="SI", 5, 1) -> 5 | N52: =IF(H52="SI", 5, 1) -> 5 | O52: =IF(I52="SI", 5, 1) -> 5 | P52: =IF(J52="SI", 5, 1) -> 1 | Q52: =IF(K52="SI", 5, 1) -> 5 | R52: =IF(L52="SI", 5, 1) -> 5 | S52: 4.3703704 | T52: 4.1724138 | U52: =SUM(M52:T52) -> 34.542784 | V52: =(Tabla1[[#This Row],[Total]]/$U$53)*1000 -> 21.279965 | W52: =ROUND(Tabla1[[#This Row],[Normalización]],0) -> 21
U53: =SUM(U2:U52) -> 1623.2538 | V53: =SUM(V2:V52) -> 1000 | W53: =SUBTOTAL(109,Tabla1[Aproximación a la unidad]) -> 1000

Sheet Tb
A3: Etiquetas de fila | B3: Suma de Puntaje para la gobernanza | C3: Suma de Puntaje máximo del indicador | E3: Dimension | F3: Porcentaje | G3: Porcentaje restante | I3: Indicadores
A4: Análisis institucional | B4: 27 | C4: 59 | E4: =A4 -> Análisis institucional | F4: =GETPIVOTDATA("Suma de Puntaje para la gobernanza",$A$3,"Dimensión","Análisis institucional")/GETPIVOTDATA("Suma de Puntaje máximo del indicador",$A$3,"Dimensión","Análisis institucional") -> 0.45762712 | G4: =200%-F4 -> 1.5423729 | I4: Base
A5: Análisis jurídico-normativo | B5: 42.4 | C5: 96 | E5: =A5 -> Análisis jurídico-normativo | F5: =GETPIVOTDATA("Suma de Puntaje para la gobernanza",$A$3,"Dimensión","Análisis jurídico-normativo")/GETPIVOTDATA("Suma de Puntaje máximo del indicador",$A$3,"Dimensión","Análisis jurídico-normativo") -> 0.44166667 | G5: =200%-F5 -> 1.5583333 | I5: Parte visble | J5: 1
A6: Biofísica y ecológica | B6: 61.3 | C6: 91 | E6: =A6 -> Biofísica y ecológica | F6: =GETPIVOTDATA("Suma de Puntaje para la gobernanza",$A$3,"Dimensión","Biofísica y ecológica")/GETPIVOTDATA("Suma de Puntaje máximo del indicador",$A$3,"Dimensión","Biofísica y ecológica") -> 0.67362637 | G6: =200%-F6 -> 1.3263736 | I6: Parte oculta | J6: 1
A7: Cambio climático y gestión del riesgo | B7: 49 | C7: 134 | E7: =A7 -> Cambio climático y gestión del riesgo | F7: =GETPIVOTDATA("Suma de Puntaje para la gobernanza",$A$3,"Dimensión","Cambio climático y gestión del riesgo ")/GETPIVOTDATA("Suma de Puntaje máximo del indicador",$A$3,"Dimensión","Cambio climático y gestión del riesgo ") -> 0.36567164 | G7: =200%-F7 -> 1.6343284
A8: Económica | B8: 74.5 | C8: 82 | E8: =A8 -> Económica | F8: =GETPIVOTDATA("Suma de Puntaje para la gobernanza",$A$3,"Dimensión","Económica")/GETPIVOTDATA("Suma de Puntaje máximo del indicador",$A$3,"Dimensión","Económica") -> 0.90853659 | G8: =200%-F8 -> 1.0914634
A9: Gestión y evaluación ambiental | B9: 33 | C9: 57 | E9: =A9 -> Gestión y evaluación ambiental | F9: =GETPIVOTDATA("Suma de Puntaje para la gobernanza",$A$3,"Dimensión","Gestión y evaluación ambiental")/GETPIVOTDATA("Suma de Puntaje máximo del indicador",$A$3,"Dimensión","Gestión y evaluación ambiental") -> 0.57894737 | G9: =200%-F9 -> 1.4210526
A10: Social | B10: 77 | C10: 89 | E10: =A10 -> Social | F10: =GETPIVOTDATA("Suma de Puntaje para la gobernanza",$A$3,"Dimensión","Social")/GETPIVOTDATA("Suma de Puntaje máximo del indicador",$A$3,"Dimensión","Social") -> 0.86516854 | G10: =200%-F10 -> 1.1348315
A11: Subsector de energía eléctrica | B11: 62 | C11: 91 | E11: =A11 -> Subsector de energía eléctrica | F11: =GETPIVOTDATA("Suma de Puntaje para la gobernanza",$A$3,"Dimensión","Subsector de energía eléctrica")/GETPIVOTDATA("Suma de Puntaje máximo del indicador",$A$3,"Dimensión","Subsector de energía eléctrica") -> 0.68131868 | G11: =200%-F11 -> 1.3186813
A12: Subsector de hidrocarburos | B12: 48 | C12: 122 | E12: =A12 -> Subsector de hidrocarburos | F12: =GETPIVOTDATA("Suma de Puntaje para la gobernanza",$A$3,"Dimensión","Subsector de hidrocarburos ")/GETPIVOTDATA("Suma de Puntaje máximo del indicador",$A$3,"Dimensión","Subsector de hidrocarburos ") -> 0.39344262 | G12: =200%-F12 -> 1.6065574
A13: Subsector de minería | B13: 33 | C13: 83 | E13: =A13 -> Subsector de minería | F13: =GETPIVOTDATA("Suma de Puntaje para la gobernanza",$A$3,"Dimensión","Subsector de minería ")/GETPIVOTDATA("Suma de Puntaje máximo del indicador",$A$3,"Dimensión","Subsector de minería ") -> 0.39759036 | G13: =200%-F13 -> 1.6024096
A14: Transición energética justa | B14: 64 | C14: 96 | E14: =A14 -> Transición energética justa | F14: =GETPIVOTDATA("Suma de Puntaje para la gobernanza",$A$3,"Dimensión","Transición energética justa")/GETPIVOTDATA("Suma de Puntaje máximo del indicador",$A$3,"Dimensión","Transición energética justa") -> 0.66666667 | G14: =200%-F14 -> 1.3333333
A15: Total general | B15: 571.2 | C15: 1000
A21: Etiquetas de fila | B21: Suma de Puntaje para la gobernanza | C21: Suma de Puntaje máximo del indicador | E21: Objetivos | F21: Porcentaje
A22: Efectividad | B22: 246.8 | C22: 360 | E22: =A22 -> Efectividad | F22: =GETPIVOTDATA("Suma de Puntaje para la gobernanza",$A$21,"Objetivos","Efectividad")/GETPIVOTDATA("Suma de Puntaje máximo del indicador",$A$21,"Objetivos","Efectividad") -> 0.68555556
A23: Equidad | B23: 154.6 | C23: 283 | E23: =A23 -> Equidad | F23: =GETPIVOTDATA("Suma de Puntaje para la gobernanza",$A$21,"Objetivos","Equidad")/GETPIVOTDATA("Suma de Puntaje máximo del indicador",$A$21,"Objetivos","Equidad") -> 0.54628975
A24: Receptividad | B24: 127 | C24: 253 | E24: =A24 -> Receptividad | F24: =GETPIVOTDATA("Suma de Puntaje para la gobernanza",$A$21,"Objetivos","Receptividad")/GETPIVOTDATA("Suma de Puntaje máximo del indicador",$A$21,"Objetivos","Receptividad") -> 0.50197628
A25: Robustez | B25: 42.8 | C25: 104 | E25: =A25 -> Robustez | F25: =GETPIVOTDATA("Suma de Puntaje para la gobernanza",$A$21,"Objetivos","Robustez")/GETPIVOTDATA("Suma de Puntaje máximo del indicador",$A$21,"Objetivos","Robustez") -> 0.41153846
A26: Total general | B26: 571.2 | C26: 1000
A29: Etiquetas de fila | B29: Suma de Puntaje para la gobernanza | C29: Suma de Puntaje máximo del indicador
A30: Anticipación | B30: 55 | C30: 131
A31: Capacidad - Capacidad institucional | B31: 6 | C31: 21
A32: Capacidad - Capacidad institucional para actuar | B32: 1 | C32: 14
A33: Coordinación, dirección, capacidad y eficiencia | B33: 25 | C33: 40
A34: Eficiencia | B34: 185.8 | C34: 240
A35: Flexibilidad y Adaptación | B35: 72 | C35: 122
A36: Información | B36: 13 | C36: 42
A37: Información | B37: 6 | C37: 21
A38: Justicia | B38: 47 | C38: 103
A39: Legitimidad | B39: 10.8 | C39: 35
A40: Legitimidad - Cumplimiento legal | B40: 26 | C40: 48
A41: Participación | B41: 24 | C41: 24
... A48: Total general | B48: 571.2 | C48: 1000
A50: Etiquetas de fila | B50: Suma de Porcentaje alcanzado | E50: Indicador | F50: Porcentaje
A51: Análisis institucional | B51: 131.57895
A52: Acceso a justicia | B52: 10.526316 | E52: =A52 -> Acceso a justicia | F52: =GETPIVOTDATA("Porcentaje alcanzado",$A$50,"Dimensión","Análisis institucional","Índice / Indicador","Acceso a justicia") -> 10.526316
A53: Coordinación intersectorial | B53: 21.052632 | E53: =A53 -> Coordinación intersectorial | F53: =GETPIVOTDATA("Porcentaje alcanzado",$A$50,"Dimensión","Análisis institucional","Índice / Indicador","Coordinación intersectorial") -> 21.052632
A54: Puntaje del sector de minas y energía en el índice de Desempeño Institucional | B54: 100 | E54: =A54 -> Puntaje del sector de minas y energía en el índice de Desempeño Institucional | F54: =GETPIVOTDATA("Porcentaje alcanzado",$A$50,"Dimensión","Análisis institucional","Índice / Indicador","Puntaje del sector de minas y energía en el índice de Desempeño Institucional") -> 100
A55: Análisis jurídico-normativo | B55: 219.07268
A56: Análisis de impacto regulatorio con dimensión ambiental | B56: 72.857143 | E56: =A56 -> Análisis de impacto regulatorio con dimensión ambiental | F56: =GETPIVOTDATA("Porcentaje alcanzado",$A$50,"Dimensión","Análisis jurídico-normativo","Índice / Indicador","Análisis de impacto regulatorio con dimensión ambiental") -> 72.857143
...

Sheet Resultado
